Workbook

Sheet 09_Dashboard
A1: upGrad School of Technology | I1: Admission Cycle | K1: As of | M1: Auto-updating
A2: LOAN OPERATIONS MANAGEMENT SYSTEM | I2: ='02_Configuration'!B83 | K2: ='02_Configuration'!B82 | M2: Formula-driven
A4: FILTERS | B4: Campus | C4: ='08_Dashboard_Tables'!B4 | D4: Critical | E4: ='08_Dashboard_Tables'!B7 | F4: Loan Required | G4: ='08_Dashboard_Tables'!B8 | H4: Dup Vendor | I4: ='08_Dashboard_Tables'!B9 | K4: Edit filters on 08_Dashboard_Tables!B4:B9 → Ops lists honor them in v2. KPI strip = global truth.
A6: EXECUTIVE SNAPSHOT
A7: Total Students | B7: Need Loan | C7: Processing | D7: Docs Pending | E7: Sanctioned | F7: Disbursed | G7: Rejected
A8: ='08_Dashboard_Tables'!B13 | B8: ='08_Dashboard_Tables'!B14 | C8: ='08_Dashboard_Tables'!B16 | D8: ='08_Dashboard_Tables'!B17 | E8: ='08_Dashboard_Tables'!B18 | F8: ='08_Dashboard_Tables'!B19 | G8: ='08_Dashboard_Tables'!B20
A10: Need FLDG | B10: Need Vidyalakshmi | C10: Critical Cases | D10: Dup Vendors | E10: Avg Vendors | F10: With Vendor | G10: Not Started
A11: ='08_Dashboard_Tables'!B21 | B11: ='08_Dashboard_Tables'!B22 | C11: ='08_Dashboard_Tables'!B23 | D11: ='08_Dashboard_Tables'!B24 | E11: ='08_Dashboard_Tables'!B25 | F11: ='08_Dashboard_Tables'!B26 | G11: ='08_Dashboard_Tables'!B27
A13: LOAN FUNNEL | F13: VENDOR PERFORMANCE
A14: Stage | B14: Students | C14: vs Need Loan | D14: Bar | F14: Vendor | G14: Unique | H14: Apps | I14: In Status | J14: Sanctioned | K14: Critical | L14: Appr%
A15: ='08_Dashboard_Tables'!D13 | B15: ='08_Dashboard_Tables'!E13 | C15: ='08_Dashboard_Tables'!F13 | D15: =IF($B$15=0,"",REPT("█",ROUND(B15/$B$15*20,0))) | F15: ='08_Dashboard_Tables'!A38 | G15: ='08_Dashboard_Tables'!B38 | H15: ='08_Dashboard_Tables'!C38 | I15: ='08_Dashboard_Tables'!D38 | J15: ='08_Dashboard_Tables'!E38 | K15: ='08_Dashboard_Tables'!F38 | L15: ='08_Dashboard_Tables'!G38
A16: ='08_Dashboard_Tables'!D14 | B16: ='08_Dashboard_Tables'!E14 | C16: ='08_Dashboard_Tables'!F14 | D16: =IF($B$15=0,"",REPT("█",ROUND(B16/$B$15*20,0))) | F16: ='08_Dashboard_Tables'!A39 | G16: ='08_Dashboard_Tables'!B39 | H16: ='08_Dashboard_Tables'!C39 | I16: ='08_Dashboard_Tables'!D39 | J16: ='08_Dashboard_Tables'!E39 | K16: ='08_Dashboard_Tables'!F39 | L16: ='08_Dashboard_Tables'!G39
A17: ='08_Dashboard_Tables'!D15 | B17: ='08_Dashboard_Tables'!E15 | C17: ='08_Dashboard_Tables'!F15 | D17: =IF($B$15=0,"",REPT("█",ROUND(B17/$B$15*20,0))) | F17: ='08_Dashboard_Tables'!A40 | G17: ='08_Dashboard_Tables'!B40 | H17: ='08_Dashboard_Tables'!C40 | I17: ='08_Dashboard_Tables'!D40 | J17: ='08_Dashboard_Tables'!E40 | K17: ='08_Dashboard_Tables'!F40 | L17: ='08_Dashboard_Tables'!G40
A18: ='08_Dashboard_Tables'!D16 | B18: ='08_Dashboard_Tables'!E16 | C18: ='08_Dashboard_Tables'!F16 | D18: =IF($B$15=0,"",REPT("█",ROUND(B18/$B$15*20,0))) | F18: ='08_Dashboard_Tables'!A41 | G18: ='08_Dashboard_Tables'!B41 | H18: ='08_Dashboard_Tables'!C41 | I18: ='08_Dashboard_Tables'!D41 | J18: ='08_Dashboard_Tables'!E41 | K18: ='08_Dashboard_Tables'!F41 | L18: ='08_Dashboard_Tables'!G41
A19: ='08_Dashboard_Tables'!D17 | B19: ='08_Dashboard_Tables'!E17 | C19: ='08_Dashboard_Tables'!F17 | D19: =IF($B$15=0,"",REPT("█",ROUND(B19/$B$15*20,0))) | F19: ='08_Dashboard_Tables'!A42 | G19: ='08_Dashboard_Tables'!B42 | H19: ='08_Dashboard_Tables'!C42 | I19: ='08_Dashboard_Tables'!D42 | J19: ='08_Dashboard_Tables'!E42 | K19: ='08_Dashboard_Tables'!F42 | L19: ='08_Dashboard_Tables'!G42
A20: ='08_Dashboard_Tables'!D18 | B20: ='08_Dashboard_Tables'!E18 | C20: ='08_Dashboard_Tables'!F18 | D20: =IF($B$15=0,"",REPT("█",ROUND(B20/$B$15*20,0)))
F21: Overlap matrix → see 05_Vendor_Analytics (heatmap)
A22: CAMPUS PERFORMANCE
A23: Campus | B23: Total | C23: Need Loan | D23: Processing | E23: Sanctioned | F23: Disbursed | G23: Rejected | H23: Critical
A24: ='08_Dashboard_Tables'!H13 | B24: ='08_Dashboard_Tables'!I13 | C24: ='08_Dashboard_Tables'!J13 | D24: ='08_Dashboard_Tables'!K13 | E24: ='08_Dashboard_Tables'!L13 | F24: ='08_Dashboard_Tables'!M13 | G24: ='08_Dashboard_Tables'!N13 | H24: ='08_Dashboard_Tables'!O13
A25: ='08_Dashboard_Tables'!H14 | B25: ='08_Dashboard_Tables'!I14 | C25: ='08_Dashboard_Tables'!J14 | D25: ='08_Dashboard_Tables'!K14 | E25: ='08_Dashboard_Tables'!L14 | F25: ='08_Dashboard_Tables'!M14 | G25: ='08_Dashboard_Tables'!N14 | H25: ='08_Dashboard_Tables'!O14
A27: RISK DASHBOARD | D27: STUDENT AGEING | H27: DROP-OFF REASONS
A28: Flag | B28: Count | D28: Bucket | E28: Count | H28: Reason | I28: Count
A29: ='08_Dashboard_Tables'!A48 | B29: ='08_Dashboard_Tables'!B48 | D29: ='08_Dashboard_Tables'!D48 | E29: ='08_Dashboard_Tables'!E48 | F29: =IF(SUM($E$29:$E$34)=0,"",REPT("█",ROUND(E29/MAX($E$29:$E$34)*15,0))) | H29: ='08_Dashboard_Tables'!G48 | I29: ='08_Dashboard_Tables'!H48
A30: ='08_Dashboard_Tables'!A49 | B30: ='08_Dashboard_Tables'!B49 | D30: ='08_Dashboard_Tables'!D49 | E30: ='08_Dashboard_Tables'!E49 | F30: =IF(SUM($E$29:$E$34)=0,"",REPT("█",ROUND(E30/MAX($E$29:$E$34)*15,0))) | H30: ='08_Dashboard_Tables'!G49 | I30: ='08_Dashboard_Tables'!H49
A31: ='08_Dashboard_Tables'!A50 | B31: ='08_Dashboard_Tables'!B50 | D31: ='08_Dashboard_Tables'!D50 | E31: ='08_Dashboard_Tables'!E50 | F31: =IF(SUM($E$29:$E$34)=0,"",REPT("█",ROUND(E31/MAX($E$29:$E$34)*15,0))) | H31: ='08_Dashboard_Tables'!G50 | I31: ='08_Dashboard_Tables'!H50
A32: ='08_Dashboard_Tables'!A51 | B32: ='08_Dashboard_Tables'!B51 | D32: ='08_Dashboard_Tables'!D51 | E32: ='08_Dashboard_Tables'!E51 | F32: =IF(SUM($E$29:$E$34)=0,"",REPT("█",ROUND(E32/MAX($E$29:$E$34)*15,0))) | H32: ='08_Dashboard_Tables'!G51 | I32: ='08_Dashboard_Tables'!H51
A33: ='08_Dashboard_Tables'!A52 | B33: ='08_Dashboard_Tables'!B52 | D33: ='08_Dashboard_Tables'!D52 | E33: ='08_Dashboard_Tables'!E52 | F33: =IF(SUM($E$29:$E$34)=0,"",REPT("█",ROUND(E33/MAX($E$29:$E$34)*15,0))) | H33: ='08_Dashboard_Tables'!G52 | I33: ='08_Dashboard_Tables'!H52
A34: ='08_Dashboard_Tables'!A53 | B34: ='08_Dashboard_Tables'!B53 | D34: ='08_Dashboard_Tables'!D53 | E34: ='08_Dashboard_Tables'!E53 | F34: =IF(SUM($E$29:$E$34)=0,"",REPT("█",ROUND(E34/MAX($E$29:$E$34)*15,0))) | H34: ='08_Dashboard_Tables'!G53 | I34: ='08_Dashboard_Tables'!H53
A35: ='08_Dashboard_Tables'!A54 | B35: ='08_Dashboard_Tables'!B54 | H35: ='08_Dashboard_Tables'!G54 | I35: ='08_Dashboard_Tables'!H54
A36: ='08_Dashboard_Tables'!A55 | B36: ='08_Dashboard_Tables'!B55 | H36: ='08_Dashboard_Tables'!G55 | I36: ='08_Dashboard_Tables'!H55
A37: ='08_Dashboard_Tables'!A56 | B37: ='08_Dashboard_Tables'!B56 | H37: ='08_Dashboard_Tables'!G56 | I37: ='08_Dashboard_Tables'!H56
A38: ='08_Dashboard_Tables'!A57 | B38: ='08_Dashboard_Tables'!B57
A41: LOAN STATUS DISTRIBUTION | F41: TOP PENDING STUDENTS
A42: Stage | B42: Count | C42: Share | F42: See sheet 10_Ops_Views for live Top Pending, FLDG list, Vidyalakshmi list, and student search.
A43: ='08_Dashboard_Tables'!A62 | B43: ='08_Dashboard_Tables'!B62 | C43: =IF(SUM($B$43:$B$54)=0,0,B43/SUM($B$43:$B$54)) | D43: =IF(SUM($B$43:$B$54)=0,"",REPT("█",ROUND(B43/MAX($B$43:$B$54)*18,0)))
A44: ='08_Dashboard_Tables'!A63 | B44: ='08_Dashboard_Tables'!B63 | C44: =IF(SUM($B$43:$B$54)=0,0,B44/SUM($B$43:$B$54)) | D44: =IF(SUM($B$43:$B$54)=0,"",REPT("█",ROUND(B44/MAX($B$43:$B$54)*18,0))) | F44: QUICK NAVIGATION
A45: ='08_Dashboard_Tables'!A64 | B45: ='08_Dashboard_Tables'!B64 | C45: =IF(SUM($B$43:$B$54)=0,0,B45/SUM($B$43:$B$54)) | D45: =IF(SUM($B$43:$B$54)=0,"",REPT("█",ROUND(B45/MAX($B$43:$B$54)*18,0))) | F45: → 04_Student_360 — One row per student
A46: ='08_Dashboard_Tables'!A65 | B46: ='08_Dashboard_Tables'!B65 | C46: =IF(SUM($B$43:$B$54)=0,0,B46/SUM($B$43:$B$54)) | D46: =IF(SUM($B$43:$B$54)=0,"",REPT("█",ROUND(B46/MAX($B$43:$B$54)*18,0))) | F46: → 05_Vendor_Analytics — Unique vs Apps + Overlap heatmap
A47: ='08_Dashboard_Tables'!A66 | B47: ='08_Dashboard_Tables'!B66 | C47: =IF(SUM($B$43:$B$54)=0,0,B47/SUM($B$43:$B$54)) | D47: =IF(SUM($B$43:$B$54)=0,"",REPT("█",ROUND(B47/MAX($B$43:$B$54)*18,0))) | F47: → 06_Stage_Analytics — Full funnel
...

Sheet 01_Master_Data
A1: S. No | B1: Name | C1: Mobile Number | D1: Provisional ID | E1: Campus | F1: Need Loan (SST input) | G1: Criticality (SST INput) | H1: Scholarship | I1: Loan Amt req | J1: 12th percentage | K1: Co-Applicant Relation | L1: Occupation | M1: Annual Income | N1: Income Proof | O1: Any other loan | P1: Co-applcant Cibil | Q1: Co-lateral | R1: Co-lateral details | S1: SST Remarks | T1: Pranjal Comments | U1: Loan required (Latest) | V1: Shared to ICICI | W1: Shared to Propelld | X1: Shared to Study4Buddy | Y1: Shared to Poonawala Fincorp | Z1: Shared to GyanDhan | AA1: Initial Case Status | AB1: CurrentCase Status (started on 31/7) | AC1: Tentative Loan Date | AD1: Intent to be Reverted to SST | AE1: Mentor Flag | AF1: SST Comments | AG1: Loan Stage | AH1: Loan Status | AI1: Need FLDG attention | AJ1: Needs Vishwa's attention | AK1: Special Vidyalaksmi attention | AL1: Reason if not started | AM1: Column 37 | AN1: Banker Status | AO1: Column 39 | AP1: Column 40 | AQ1: Column 41
A2: 1 | B2: Priyanshu Jena | C2: 7606059075 | D2: PROV260602396 | E2: SSAHE | F2: Yes | G2: Non Critical | H2: 0.05 | I2: 25 | J2: 66.5 | K2: Father | L2: Salaried | M2: 13 | N2: ITR | O2: No | P2: NA | Q2: No | R2: NA | S2: Waiting for the bank to reach them out Need assitance from us | T2: 9/7/26: Requires loan of 25Lakhs, good cibil score, good income, please reach out to this student , bank hasn't called back yet 18/7: Ongoing on with ICICI bank. 28/7 : Student suggest that process has been completed from icici but they haven't reverted anything about this one 30/7 : Student loan has been rejected by icici due to other bank , | U2: Yes | V2: Yes | W2: No | X2: No | Y2: No | Z2: Yes | AA2: Control | AB2: Control | AG2: Ongoing | AH2: Processing by Icici | AI2: No | AJ2: No | AK2: No
A3: 2 | B3: Arithra Kabiraj | C3: 7990739081 | D3: PROV260501340 | E3: SSAHE | F3: Yes | G3: Non Critical | H3: 0.05 | I3: 25 | J3: 81 | K3: Father | L3: Salaried | M3: 7.8 | N3: ITR | O3: Yes | P3: 720 | Q3: Yes | R3: Residential | S3: Waiting for the bank to reach them out Need assitance from us | T3: 9/7/26 : DNP *15/7/26: In talks with Propelled : Shared to ICICI : Also trying at their level 20/7: Ongoing in talks with SBI as well. 29/7: Propell offering at 15%, have also started with GyanDhan | U3: Yes | V3: Yes | W3: Yes | X3: No | Y3: No | Z3: Yes | AA3: Control | AB3: Control | AG3: Ongoing | AH3: Processing by Propelld, Loan sanctioned by gyan dhan | AI3: No | AJ3: No | AK3: No
A4: 3 | B4: Ayansh Maurya | C4: 6306995363 | D4: PROV260610670 | E4: SSAHE | F4: Yes | G4: Non Critical | H4: 0.125 | I4: 26 | J4: 72.8 | K4: Uncle | L4: Salaried | M4: 9 | N4: Salary Slip | O4: Yes | P4: 759 | Q4: No | R4: NA | S4: Waiting for the bank to reach them out Need assitance from us | T4: 9/7/26 : DNP 15/7/26 : 10th %age- 90.16 12th %age- 72.8 Loan Amount- 24 lakhs Co applicant- Gyan Prakash (uncle) Profession- Assistance professor Salary- 75k per month Cibil Score- 759 Existing emi- Rs14710 Contact number- 81150 37832 20/7: In talks with ICICI, have suggested to apply elsewhere as well. 28/7 : Case was rejected by icici and gyan dhan both . icici rejected his case due to FOIR. 29/7 : Mother called again , will try to processs it on mother, before it was processed on uncle's name. Gyan dhan came back telling this case is doable onn whatsapp. Moving it from control to risk 31/7 : Gyandhan is asking for relationship proof. have told gyandhan to connect with them. Mother called and is worried about the loan, has different offers as well. | U4: Yes | V4: Yes | W4: No | X4: No | Y4: No | Z4: Yes | AA4: Risk | AB4: Risk | AG4: Ongoing | AH4: Processing by Icici | AI4: No | AJ4: No | AK4: No
A5: 4 | B5: Harshit Singhi | C5: 9883379315 | D5: PROV260502866 | E5: SSAHE | F5: Yes | G5: Loan not required | H5: 0.05 | I5: 25 | J5: 70 | K5: Father | L5: Business | M5: 7 | N5: ITR | O5: No | P5: NA | Q5: No | R5: NA | S5: Waiting for the bank to reach them out Need assitance from us | T5: 9/7/26 : HAd in depth conversation, student already has 10L funds, and 10L he would require loan, which he would not avail in this year. Suggested him to pay the fees within this month. | U5: No | V5: No | W5: No | AA5: Not required | AB5: Not required | AG5: Not required | AK5: No
A6: 5 | B6: Prem Sandeep Dipke | C6: 8605831946 | D6: PROV260506859 | E6: ADYPU | F6: Yes | G6: Non Critical | H6: 0.125 | I6: 25 | J6: 58 | K6: Father | L6: Salaried | M6: 3 | N6: Income Certificate | O6: No | P6: NA | Q6: No | R6: NA | S6: Propelled -24Lakh , Rate of intrest :11-12%, Going with Propelled | T6: 9/7/26 : Loan process has begun through propelld , they have offer 10L at 13%, he has some expectation of 10%, have spoken to student , student will make me talk to the father tomorrow. Father's number : 9359685429 10/7/26 : Called father , DNP. Father called back : not at all happy with 13% ROI, he said it would be too much to pay. Father was outside, so he told he would call me by evening to discuss this . ICICI hasn't reached out to them 21/7 : Pranjal : Have to be processed by GyanDhan. Student hasn't talked to any banks. Yearly incomr : 5L, ITR filed : No, Profession : Travel agent , Rental income : 0, started with propelled but 14% interest is too much 30/7: Approved | U6: Yes | V6: No | W6: Yes | AA6: Control | AB6: Control | AG6: Ongoing | AH6: Loan sanctioned by gyan dhan | AI6: No | AJ6: No | AK6: No
A7: 6 | B7: Manthan upmanyu | C7: 9399297905 | D7: PROV260604114 | E7: SSAHE | F7: Yes | G7: Non Critical | H7: 0.175 | I7: 25 | J7: 85 | K7: Mother | L7: Bussiness | M7: 8 | N7: ITR | O7: No | P7: NA | Q7: No | R7: NA | S7: Waiting for the bank to reach them out Need assitance from us | T7: 9/7/26 : Student was communicated wrong in terms of hostel fees. Mother was furious listening to the hostel fees due to miscommunication. Have suggested the student to drop me as well as to admissions team an email regarding the same. Counselor also committed 20% scholarship against which the student has got 17.5% ( 10% merit based + 7.5% EWS ) 20/7 : Need intent check from SST team. 27/7 : DNP 29/7 : DNP || spoke to the student , the student would pay the fees tomorrow. has requested for a single room if possible. Doesn't need loan for this year. Moving from risk to control | U7: No | V7: No | W7: No | X7: No | Y7: No | Z7: No | AA7: Control | AB7: Control | AD7: Student had some issue regarding fees and scholarship, wanted to check if that is sorted before moving to the loan part. Souhardya Bose Multiple calls have gone to this student, Please speak to him and let me know if his issues are resolved and is he willing to go for loan. Souhardya Bose Had a conversation with student , doesn't need SSt intervention : 29/7/26 | AG7: Not required
A8: 7 | B8: Akchat Bharti | C8: 9031350334 | D8: PROV1000000431 | E8: SSAHE | F8: Yes | G8: Non Critical | H8: 0.05 | I8: 22 | J8: 81.12 | K8: Father | L8: Salaried | M8: 7 | N8: ITR | O8: No | P8: 728 | Q8: No | R8: NA | S8: Waiting for the bank to reach them out Need assitance from us | T8: 9/7/26 : He is from Jharkhand, he is taking loan from Jharkhand govt of 15L at 4%, the loan is in process , the rest of the amount he will be take from diffferent banks. 20/7: Jharkahdn SCC is in process, Rejected propelld due to high int rate, next ICICI and Gyan Dhan Update by Gyandhan Learner got loan from govt scheme (jharkhand), cannot process another loan on same profile 28/7 : Semester fees will be paid by next week | U8: Yes | V8: No | W8: No | X8: No | Y8: No | Z8: No | AA8: Control | AB8: Control | AG8: Ongoing | AH8: Processing by Icici, Processing by GyanDhan, State Scheme | AI8: No | AJ8: No
A9: 8 | B9: SamarthG | C9: 9242410155 | D9: PROV1000000341 | E9: ADYPU | F9: Yes | G9: Loan not required | H9: 0.15 | I9: 25 | J9: 89 | K9: Father | L9: Self-Employed | M9: 7 | N9: Income Certificate | O9: No | P9: NA | Q9: No | R9: NA | S9: Waiting for the bank to reach them out Need assitance from us | T9: 9/7/26 This student would visit on 25th of july to ADYPU and would pay the fees there only. Please be in touch with them, they dont require the loan. | U9: No | AA9: Not required | AB9: Not required | AG9: Not required
A10: 9 | B10: AAVANI JITH | C10: 8091531491 | D10: PROV1000000399 | E10: SSAHE | F10: Yes | G10: Non Critical | H10: 0.1 | I10: 23 | J10: NA | K10: Father | L10: Salaried | M10: 10.2 | N10: Income Certificate | O10: Yes | P10: 772 | Q10: No | R10: NA | S10: its a positive case , student is going frwd with icici bank just need documents | T10: 9/7/26 : ICICI has rejected the loan due to bounce issues , they are in touch with the propelld. Propelld is processing it , have sent them the message to check the status on the saMe. 13/7/26 : Father called to check the status on the application, have asked propelld for the status 21/7: Sanctioned UTR Number : AUBLN62026072146425058 | U10: Yes | V10: No | W10: Yes | AA10: Control | AB10: Control | AG10: Disbursed | AH10: Disbursed, Loan sanctioned by Propelld | AI10: No | AJ10: No
A11: 10 | B11: Gulshan Kumar | C11: 8877535347 | D11: PROV1000000313 | E11: SSAHE | F11: Yes | G11: Non Critical | H11: 0.25 | I11: 22.5 | J11: 76 | K11: Father | L11: Farmer | M11: 5 | N11: Income Certificate | O11: No | P11: 750 | Q11: No | R11: NA | S11: its positive from icici bank, they are taking loan, need documents | T11: 9/7/26 : Student has got the call from ICICI bank , 1 week back , the student has not submitted the documents yet as the bank didn't reach out to him for the document. 10/7/26 : ICICI has reached out to the student, have shared the document list , they are taking this ahead 17/7/26 : Checked with the student, have sent the document to icici , they haven't responded yet 23/7: All process left only sanction done. 29/7 : His loan is still under process but he has paid the sem fees and hostel fees from their side | U11: Yes | V11: Yes | W11: No | AA11: Control | AB11: Control | AG11: Ongoing | AH11: Processing by Icici | AI11: No | AJ11: No | AK11: No
A12: 11 | B12: Prashant Kumar Raj | C12: 9376384908 | D12: PROV1000000265 | E12: SSAHE | F12: Yes | G12: Non Critical | H12: 0.2 | I12: 15 | J12: 80.2 | K12: Uncle | L12: business | M12: 15 | N12: ITR | O12: Yes | P12: 782 | Q12: No | R12: NA | S12: Waiting for the bank to reach them out Need assitance from us | T12: 9/7/26 : Have shared the number to ICICI , is looking for loan 15/7/26 : Shared to propelld , propelld will call them, icici rejected the case, 699 cibil. Father's income : 30K/m, Mom's shop : 3.5L , ITR mom only. Uncle cibil 20/7: Ongoing in various banks (Axis, propell, gyandhan) 29/7 : Have applied through PM vidyalakshmi, currently in the bank to get the loan. SBI - 7.5L , student says he would get loan by 15th Aug, I have pushed him to get it by 10th. 3/8 : Student have applied through bank and is asking for extension | U12: Yes | V12: Yes | W12: Yes | X12: No | Y12: No | Z12: Yes | AA12: Control | AB12: Control | AG12: Ongoing | AH12: Processing by Icici, Processing by GyanDhan | AI12: No | AJ12: No | AK12: Yes
A13: 12 | B13: Ayushman Tiwari | C13: 9109536213 | D13: PROV1000000316 | E13: SSAHE | F13: Yes | G13: Loan not required | H13: NA | I13: 25 | J13: NA | K13: Father | L13: Salaried | M13: 22 | N13: ITR | O13: Yes | P13: 783 | Q13: No | R13: NA | S13: Waiting for the bank to reach them out Need assitance from us | T13: 9/7/26 : Student will pay the fees of first sem + hostel., he is asking how to pay, have shared the number to SST , have told them to call. have told him that sooner you pay the fees, sooner you’ll be able to book the hostel room | U13: No | V13: No | W13: No | AA13: Not required | AB13: Not required | AG13: Not required
A14: 13 | B14: Bhupendra Saini | C14: 7307944285 | D14: PROV260503144 | E14: SSAHE | F14: Yes | G14: Non Critical | H14: 0.15 | I14: 25 | J14: 68 | K14: Father | L14: Salaried | M14: 8 | N14: ITR | O14: Yes | P14: 746 | Q14: No | R14: NA | S14: Waiting for the bank to reach them out Need assitance from us | T14: 9/7/26 : Requires loan and have shared his details with ICICI and propeld both to speak. He is looking for the loan of 25L. Income is correct 18/7: No revert from ICICI, have shared to more partners 21/7 : ICICI told they'll update but they haven't got back. Annual income : 7L, Father : Teacher ( Government ) , Cibil : 750, ITR filed : Yes || Processing through gyan Dhan. Mother is a housewife, father pays 90% of the emi to the interest of his sister's education 31/7: Docs submitted to GD | U14: Yes | V14: Yes | W14: Yes | AA14: Control | AB14: Control | AG14: Ongoing | AH14: Processing by GyanDhan | AI14: No | AJ14: No | AK14: No
A15: 14 | B15: Ankit Tiwari | C15: 9785596407 | D15: PROV260502511 | E15: SSAHE | F15: Yes | G15: Loan not required | H15: 0.2 | I15: 12 | J15: 82 | K15: Father | L15: Salaried | M15: 4 | N15: Income Certificate | O15: No | P15: 750 | Q15: No | R15: NA | S15: Waiting for the bank to reach them out Need assitance from us | T15: 9/7/26 : 1st year he doesnt require the loan , from the second year he requires loan. | U15: No | V15: No | W15: No | AA15: Not required | AB15: Not required | AG15: Not required
A16: 15 | B16: Harsh Kumar Hooda | C16: 7073472525 | D16: PROV1000000339 | E16: SSAHE | F16: Yes | G16: Loan not required | H16: 0.15 | I16: 20 | J16: 80.8 | K16: Father | L16: Salaried | M16: 8 | N16: Income Certificate | O16: No | P16: 750 | Q16: No | R16: NA | S16: Waiting for the bank to reach them out Need assitance from us | T16: 9/7/26 : HAd a word with student's father, student's father doesn't want to take loan , father would pay once he sees the campus through video call. Have provided the number to SST to arrange it. 10/7/26 : Student wants defence scholarship to be added || Shilpa has shown the campus today. | U16: No | V16: No | W16: No | AA16: Not required | AB16: Not required | AG16: Not required
A17: 16 | B17: Piyush Chetani | C17: 9358622412 | D17: PROV260503758 | E17: SSAHE | F17: Yes | G17: Non Critical | H17: 0.1 | I17: 24 | J17: 55 | K17: Father | L17: Self-Employed | M17: 6.5 | N17: ITR | O17: Yes | P17: 715 | Q17: No | R17: NA | S17: Waiting for the bank to reach them out Need assitance from us | T17: 10/7 : HAs got the call from Study4buddy, student has filled the icici form, 6.5 Lacs is the father income, ITR filed , Father's profession : Shop ( Self employed ). Student is worried that he is not getting +ve response from HDFC , hasn't got the call from ICICI. Student has no collateral 12/7 : Student called back, icici hasn;t called back. Student is worried about the loan. as study4buddy told he wont get the loan with this coaplicant. Shared to propelld again. 14/7 : Piyush's case has been rejected by all lenders due to low income and poor academics. Also, the father already has an existing personal loan EMI, so the income eligibility criteria are not being met. He needs to provide a strong additional co-applicant to relook the case. 21/7: Processing by propelld 31/7: Logged in with ES, GD also approved moving from risk to control | U17: Yes | V17: No | W17: Yes | AA17: Risk | AB17: Control | AG17: Ongoing | AH17: Loan sanctioned by gyan dhan | AI17: No | AJ17: No | AK17: No
A18: 17 | B18: Gautam Kumar | C18: 7033285170 | D18: PROV1000003995 | E18: SSAHE | F18: Yes | G18: Loan not required | H18: 0.2 | I18: 7 | J18: 63 | K18: Father | L18: Salaried | M18: 5.5 | N18: ITR | O18: No | P18: 750+ | Q18: No | R18: NA | S18: Waiting for the bank to reach them out Need assitance from us | T18: 10/7/26 :Called student , had a word with him, he'll pay the fees for first sem by himself and then take the loan. Parent is visiting tomorrow to the campus | U18: No | V18: No | W18: No | AA18: Not required | AB18: Not required | AG18: Not required
A19: 18 | B19: Mohammad Faizan | C19: 7541858761 | D19: PROV260500401 | E19: SSAHE | F19: Yes | G19: Non Critical | H19: 0.25 | I19: 25 | J19: 71.4 | K19: Father | L19: Salaried | M19: 8 | N19: EWS | O19: No | P19: NA | Q19: No | R19: NA | S19: Waiting for the bank to reach them out Need assitance from us | T19: 11/7 : Salaried , Salary : 8LPA, Father is talking in different banks || Loan required : need to ask father Father's number : 7782842226 Had a father , father hasn't received any call from icici || has already filled the form || Have shared the number to icici. Have talked to propelld , but father told that they would reach out to them once he processes it. Father is coming to bangalore on Monday. Requires full amount of loan 15/7 : Father came to office , he shared all the documents. Mother's PAN was left which he would share on 18th of July 18/7 : Has shared mother's PAN. suggested him to send to propelld directly. 22/7 : Propelld contacted him, again he has shared documents to propelld. 28/7 : It's with credit team of propelld,. they shall be confirming by 3pm. | U19: Yes | V19: Yes | W19: Yes | AA19: Control | AB19: Control | AG19: Ongoing | AH19: Processing by Propelld | AI19: No | AJ19: No | AK19: No
A20: 19 | B20: Vanshika Rathore | C20: 7597802620 | D20: PROV260502005 | E20: SSAHE | F20: Yes | G20: Non Critical | H20: 0.05 | I20: 20 | J20: 60 | K20: Father | L20: Salaried | M20: 29 | N20: ITR | O20: Yes | P20: NA | Q20: No | R20: NA | S20: In Conversation with HDFC | T20: 11/7 : Had contacted the mother, mother suggested that someone has died in the family, she would call back. 11/7 : Student has called back , they haven't processed any loan yet. Family would be coming on tuesday. So have to share the number with icici. have sent the reminder in my calendar to do it. 18/7 : Loan required : 20, they'll either proceed with either hdfc or icici 23/7 : Co applicant Name: Rupendra Singh Rathore Relationship: Father Co-applicant e-mail id: rsrathore81@gmail.com My mobile no. 8085351495 ITR filed:1.49 lacs Copy of last yr itr attached | U20: Yes | V20: No | W20: No | AA20: Control | AB20: Control | AG20: Ongoing | AH20: Processing at other bank, Processing by GyanDhan | AI20: No | AJ20: No | AK20: No
A21: 20 | B21: Aatharva uday Nirhali | C21: 9869868577 | D21: PROV260506354 | E21: SSAHE | F21: No | G21: Loan not required | H21: 0.05 | I21: 25 | J21: 73 | K21: Father | L21: Self-Employed | M21: 6 | N21: ITR | O21: Yes | P21: 650 | Q21: No | R21: NA | S21: Waiting for the bank to reach them out Need assitance from us | T21: 11/7 : Father wants to visit the campus within 8-15 days. Loan not required. Have shared the details with SST | U21: No | V21: No | W21: No | AA21: Not required | AB21: Not required | AG21: Not required
A22: 21 | B22: Ankit Kumar | C22: 8603034436 | D22: PROV260505049 | E22: SSAHE | F22: Yes | G22: Loan not required | H22: 0.275 | I22: 4 | J22: 73 | K22: Father | L22: Farmer | M22: 5 | N22: Income Certificate | O22: No | P22: NA | Q22: No | R22: NA | S22: Waiting for the bank to reach them out Need assitance from us | T22: 11/7 : Student is taking loan through Bihar Credit Card Scheme of 4L and the rest of the fees would be paid by student's father itself | U22: No | V22: No | W22: No | AA22: Not required | AB22: Not required | AG22: Not required
A23: 22 | B23: Rupali Yadav | C23: 9555375578 | D23: PROV260602216 | E23: SSAHE | F23: Yes | G23: Non Critical | H23: 0.15 | I23: 20 | J23: NA | K23: Self | L23: Self-Employed | M23: 5 | N23: NA | O23: No | P23: NA | Q23: No | R23: NA | S23: Waiting for the bank to reach them out Need assitance from us | T23: 11/7 : Student wants to take the loan after 2nd year, 10L would be paid by the family and 10L will be paid by the student. Father is in thailand. 14/7 : Brother called , wanted to enquire about the loan, 20/7: Have suggested her to take the loan sanction at least now, was not okay with high rate of interest, shared leads with our banks. | U23: No | AA23: Not required | AB23: Not required | AG23: Not required
A24: 23 | B24: Ankit Gupta | C24: 7870435737 | D24: PROV260501472 | E24: SSAHE | F24: Yes | G24: Non Critical | H24: 0.225 | I24: 20 | J24: 83 | K24: Father | L24: Self-Employed | M24: 6 | N24: Income certificate | O24: No | P24: NA | Q24: No | R24: NA | S24: in talks of BOI , DRCC IN BIHAR | T24: 11/7 : DNP 15/07/2026: In talks with BOI - wants BOI but BOI not providing * Pain Point - Low income but need collateral free, also not agreeing with high int as offered by Propelld * Shared profile with ICICI also to confirm that whether top up loan allowed over and above SCC schemes of states.(Student from Bihar) 20/7: DNP 23/7: Processing , is fairly confident, 27/7 : Still processing for the loan, has opened the account recently | U24: Yes | V24: yes | AA24: Control | AB24: Control | AG24: Ongoing | AH24: Processing by Icici | AK24: Yes
A25: 24 | B25: Bhuvan Tk | C25: 7259802878 | D25: PROV260606019 | E25: SSAHE | F25: Yes | G25: Critical | H25: 0.325 | I25: 20 | J25: 82 | K25: Father | L25: Salaried | M25: 2 | N25: Income certificate | O25: No | P25: NA | Q25: No | R25: NA | S25: Waiting for the bank to reach them out Need assitance from us | T25: 11/7 : this student has got revised SL for 32.5% schoolarship but POL as 22.5%, Can you please check and confirm , as its showing 22.5% on scholarship calculator and to the student on his portal. Loan : 20L , Father's income : 2LPA, no banks would be able to provide loan on this Student called again : asking for collateral loan. 16/7: Low income, but undisclosed income of rs. 25000/month from various properties. Probable sol: If NBFC's can by pass the lack of proof of income. Co app income = 12,000 unsecured loan requirement - 18,00,000 no other co app 25/7 : PM vidyalakshmi has been suggested , student told he will be able to manage post 7.5L 28/7 : Spoke to the student , guided him around the PM vidyalakshmi again. Suggested him to go to the bank and process this. | U25: Yes | V25: Yes | W25: Yes | Z25: Yes | AA25: Risk | AB25: Risk | AG25: Ongoing | AH25: Processing by GyanDhan | AJ25: No | AK25: Yes
A26: 25 | B26: Rohit Kumar | C26: 9279392342 | D26: PROV1000003417 | E26: SSAHE | F26: Yes | G26: Critical | H26: 0.075 | I26: 18 | J26: 51 | K26: Father | L26: Farmer | M26: 4 | N26: Income Certificate | O26: No | P26: NA | Q26: Yes | R26: Agricultural | S26: Waiting for the bank to reach them out Need assitance from us | T26: 11/7 : Loan required : 20L Father's income : 4L Father profession : Farmer ITR filed : No 16/7 : Not going with ICICI as do not have the requisite docs asked by the bank, waiting for a call back from propelld Probable sol: More than 3l so gyandhan or propelld may sanction, (if student is okay with the int rate) 23/7: Rejected from propelld, due to low income/Abroad Loans/low requirement/Others last option gyandhan | U26: Yes | V26: Yes | W26: Yes | Z26: Yes | AA26: Risk | AB26: Risk | AG26: Ongoing | AH26: Processing by GyanDhan | AJ26: No
A27: 26 | B27: Dhairya Sommanek | C27: 9699437102 | D27: PROV260605047 | E27: SSAHE | F27: Yes | G27: Critical | H27: 0.2 | I27: 25 | J27: 68.3 | K27: Father | L27: Self-Employed | M27: 9 | N27: Income Certificate | O27: No | P27: 790 | Q27: Yes | R27: Residential | S27: Waiting for the bank to reach them out Need assitance from us | T27: 9/7/26 : Had a conversation with the kid, looking for loan of 16 lakhs, sent it to icici 10/7/26 : Got the update from the student, he would proceed for the loan after 19th , since no PAN card available 16/7/26: Student will apply for PAN after his bday which is coming, ICICI said only issues is with PAN, based on income , loan might get sanction. Actual Problem:- Total time for PAN to come and then the loan process. Action: C+3, call back and check 21/7 : Father income : 9.5L, Mother : 6.5L, ITR filed : yes , Father's profession : Insurance business 30/7 : Icici got rejected. Student wants to talk to the Gyan dhan | U27: Yes | V27: Yes | W27: No | X27: No | Y27: No | Z27: Yes | AA27: Control | AB27: Control | AG27: Ongoing | AH27: Processing by Icici, Processing by GyanDhan | AI27: No | AJ27: Yes
A28: 27 | B28: Varsha B Patil | C28: 7090531131 | D28: PROV1000000485 | E28: SSAHE | F28: Yes | G28: Non Critical | H28: 0.125 | I28: 18 | J28: 87 | K28: Father | L28: Farmer | M28: 6 | N28: EWS | O28: Yes | P28: 644 | Q28: Yes | R28: Agricultural | S28: Only Propelled discussed and Rate of intrest is Higher-14% | T28: NATC *15/7/2026: DNP, reached out on mail *16/7/26: Has not started looking for loan, have shared the lead to all our partners *23/7: DNP 27/7 : DNP - 2nd call : Student mentioned they have some loan pending from their end for them to send | U28: Yes | V28: Yes | W28: Yes | Z28: Yes | AA28: Control | AB28: Control | AG28: Ongoing | AH28: Processing by GyanDhan | AL28: Were DNP until recently, and were not trying at personal level, have shared the leads.
A29: 28 | B29: Himanshu Kashyap | C29: 7635014278 | D29: PROV260608927 | E29: SSAHE | F29: Yes | G29: Non Critical | H29: 0.1 | I29: 10 | J29: 60.6 | K29: Father | L29: Salaried | M29: 2.76 | N29: EWS | O29: Yes | P29: 773 | Q29: Yes | R29: Agricultural | S29: Waiting for the bank to reach them out Need assitance from us | T29: 11/7 : Father's profession : Govt job ( Agriculature dept) Annual income : Loan to take : 10-12L , and the rest of the amount he would take loan. He will make me talk to the father in the evening. 21/7: DNP 21/7 : Student has already applied for collateral loan for PM vidyalakshmi. 31/7 : Student has got the top up loan on his exisisting home loan, should be disbursed in 2-3 days. | U29: Yes | V29: No | W29: No | AA29: Control | AB29: Control | AG29: Ongoing | AH29: Processing by PM vidyalakshmi
A30: 29 | B30: Aryan Santosh Pagar | C30: 9403503971 | D30: PROV1000001562 | E30: ADYPU | F30: Yes | G30: Non Critical | H30: 0 | I30: 28 | J30: 82 | K30: Father | L30: salaried | M30: 11 | N30: Income Certificate | O30: Yes | P30: NA | Q30: No | R30: NA | S30: Waiting for the bank to reach them out Need assitance from us | T30: 9/7/26 : Student has changed the campus , he wants to take loan. Student wants to take ₹16Lakhs loan. He is okay with icici and propelled, father is salaried 10/7/26 : Father confirmation required ,Details given to Aryan. 21/7 : Asked for gyan dhan and they are already processing with Central Bank. | U30: Yes | V30: Yes | W30: Yes | Z30: Yes | AA30: Control | AB30: Control | AG30: Ongoing | AH30: Processing by GyanDhan, Processing at other bank
A31: 30 | B31: Avne Deepak | C31: 8459692377 | D31: PROV1000000430 | E31: ADYPU | F31: Yes | G31: Non Critical | H31: 0.2 | I31: 15 | J31: 75 | K31: Father | L31: salaried | M31: 12 | N31: Income Certificate | O31: Yes | P31: 835 | Q31: Yes | R31: Resindetial | S31: Waiting for the bank to reach them out Need assitance from us | T31: 9/7/26 : Couldn't connect , was busy on another call *15/7/26: Call busy , seems number problem. Reached out on mail 20/7: Talked to his father, had not received any calls yet. shared the leads | U31: Yes | AA31: Control | AB31: Control | AG31: Ongoing | AH31: Processing by Icici, Processing by GyanDhan
A32: 31 | B32: Tatvagna Tandel | C32: 9054265913 | D32: PROV1000001374 | E32: ADYPU | F32: Yes | G32: Non Critical | H32: 0.2 | I32: 15 | J32: NA | K32: Father | L32: salaried | M32: 8 | N32: Salary Slip | O32: No | P32: 780 | Q32: No | R32: NA | S32: Waiting for the bank to reach them out Need assitance from us | T32: 9/7/26 : 20 lakhs, fathers income 8L, Father is a NRI, merchant navy. 10/7/26 : Spoke with the student and shared the list of required documents. He will confirm with his father and then share the documents. 21/7: Decided not to take loan, will pay the sem fees in 2-3 days | U32: No | V32: Yes | W32: Yes | AA32: Not required | AB32: Not required | AG32: Not required
A33: 32 | B33: Raj Harkal | C33: 8459935236 | D33: PROV260503159 | E33: ADYPU | F33: Yes | G33: Non Critical | H33: 0.175 | I33: 17 | J33: 68.8 | K33: Father | L33: Farmer | M33: 1 | N33: EWS | O33: Yes | P33: NA | Q33: Yes | R33: Agricultural | S33: Wating for SBI as its our partner mentioned in the website | T33: 9/7/26 : 20 lakhs, father's income : 60k/month + agriculture income : 15L , have got the call from icici filled the form today and processing the loan with icici 21/7:In process with ICICI and gyandhan. 31/7: GD (Process has successfully logged in with Poonawalla. Process initiated and all documents received with Credila and Gyandhan. ICICI status is case forwarded.) | U33: Yes | V33: Yes | W33: No | Z33: Yes | AA33: Control | AB33: Control | AG33: Ongoing | AH33: Processing by Icici, Processing by GyanDhan
A34: 33 | B34: Ashlesha sinha | C34: 7982258229 | D34: PROV260502939 | E34: SSAHE | F34: Yes | G34: Non Critical | H34: 0.125 | I34: 25 | J34: 67 | K34: Mother | L34: Self-Employed | M34: 24 | N34: Income Certificate | O34: No | P34: NA | Q34: No | R34: NA | S34: Waiting for the bank to reach them out Need assitance from us | T34: 11/7 : ITR not available, have really good income with no income proof, Has solid working income upto 1Cr in an year. Father will talk to the CA for filing the ITR. Father has nothing in pakka form. 13/7 : Parents spoke with me in length, have shared their details with PRopelld 16/7 : shared all the details with propelld. 20/7 : PRopelld approved it for 20L, with 13% interest , father and mother wanted me to share the profile with gyan dhan , have shared it 27/7 : Gyan dhan have told them that the interest to provide it for 11%, they want it 10%, still the file is pending for complete approval | U34: Yes | V34: Yes | W34: Yes | AA34: Control | AB34: Control | AG34: Ongoing | AH34: Processing by GyanDhan, Loan sanctioned by Propelld
A35: 34 | B35: suman jana | C35: 7003207775 | D35: PROV260500865 | E35: ADYPU | F35: Yes | G35: Critical | H35: 0.075 | I35: 25 | J35: 81 | K35: Father | L35: Self-Employed | M35: 2 | N35: Income Certificate | O35: No | P35: NA | Q35: Yes | R35: Residential | S35: in Discussion with SBI, Looking for option from our side | T35: 9/7/26 : dnp 10/7/26 : DNP , have sent the details to SST to check the activeness of the student . Divyansh tried reaching to the student *15/7/26- In Discussion with SBI at personal level Shared profile 21/7: DNP 23/7: DNP | U35: Yes | V35: Yes | W35: Yes | AA35: Risk | AB35: Risk | AD35: Hi Student is DNP for long and is a risk case, can we check on the activeness of the student. | AF35: will call | AG35: Ongoing | AH35: Processing at other bank | AJ35: No
A36: 35 | B36: Aman Kumar Pandey | C36: 9049158666 | D36: PROV260502978 | E36: ADYPU | F36: Yes | G36: Non Critical | H36: 0.175 | I36: 25 | J36: 73 | K36: Father | L36: salaried | M36: 4.5 | N36: EWS | O36: Yes | P36: 760+ | Q36: Yes | R36: Residential | S36: Propelld contacted didn't like what was offered , waiting for more options | T36: 9/7/26 :Student has got offer from propelld of 15%, father's income : 45k/month , have sent to icici to talk. Loan amt : 28 Lacs. 18/7: He didnt like the proposal from propelld since he could not explain properly, have shared his number with Gyan Dhan 28/7 : Student has submitted all the documents to credilla, Field verification is pending 31/7 : Student has got the placement report from adypu, arranged it and sent it ot him. he is taking loan from pnb | U36: Yes | V36: Yes | W36: Yes | AA36: Control | AB36: Control | AG36: Ongoing | AH36: Processing by GyanDhan
A37: 36 | B37: Dev Anand kumar | C37: 9162847749 | D37: PROV260600189 | E37: SSAHE | F37: Yes | G37: Non Critical | H37: 0.25 | I37: 18 | J37: 73.6 | K37: Father | L37: Salaried | M37: 5.4 | N37: Salary slip | O37: Yes | P37: 800 | Q37: No | R37: NA | S37: Waiting for the bank to reach them out Need assitance from us | T37: 12/7 : Student will take loan. Student is already talking to ICIC, HDFC, Axis. Father's income : 45k/month, Father profession : Government teacher. Tentative date for loan, : Monday tuesday loan should be processed. 14/7 : 18L loan, icici didn't approve, hdfc , student wants help now, sending it to propelld. 21/7:Rejected from everywhere , only Gyandhan option left. 31/7: Deemed not eligible by GD 01/8 : Student has not got a call from gyan so he is trying from the | U37: Yes | V37: No | W37: No | AA37: Risk | AB37: Risk | AG37: Rejected | AH37: Processing by GyanDhan, Processing by Propelld | AK37: Yes
A38: 37 | B38: Raghav Parashar | C38: 9770750570 | D38: PROV260506203 | E38: ADYPU | F38: Yes | G38: Non Critical | H38: 0.2 | I38: 25 | J38: 64.4 | K38: Father, Mother | L38: Self-Employed | M38: 5 | N38: EWS | O38: Yes | P38: NA | Q38: No | R38: No | S38: Waiting for the bank to reach them out Need assitance from us | T38: 9/7/26 : Student requires the loan of 25 L. Father's income under 5L. Have shared the details to icici and propelld both 16/7/26 : Waiting on the documents from students side ( PRopelld). 21/7 : Propelld called, student still doesnt have PAN. Once the PAN comes he would proceed with it | U38: Yes | V38: Yes | W38: Yes | AA38: Control | AB38: Control | AG38: Ongoing | AH38: Docs Pending
A39: 38 | B39: RIDDHIT BHUTRA | C39: 9662748817 | D39: PROV260606462 | E39: ADYPU | F39: Yes | G39: Non Critical | H39: 0 | I39: 25 | J39: 78.4 | K39: Father | L39: Self-Employed | M39: 8 | N39: ITR | O39: Yes | P39: 700 | Q39: No | R39: No | S39: Waiting for the bank to reach them out Need assitance from us | T39: 9/7/26 : dnp *15/7/26 - Need to call mother 9887970001 - poornima (DNP) dont need loan | U39: No | AA39: Not required | AB39: Not required | AD39: Mother just said they dont want a loan and cut the call, so maybe an intent check is needed here. | AG39: Not required
A40: 39 | B40: Aarohan prasad | C40: 7811062400 | D40: PROV260607342 | E40: ADYPU | F40: Yes | G40: Critical | H40: 0.075 | I40: 25 | J40: 60 | K40: Father | L40: Self-Employed | M40: 5 | N40: ITR | O40: No | P40: NA | Q40: No | R40: No | S40: Waiting for the bank to reach them out Need assitance from us | T40: 9/7/26 : Student wants to pay the interest and principal amt after 4 years. he has received call from icici bank and propelld, but icici has rejected due to income and propelld has higher rate of interest. Need to send their number to study4buddy. 16/7/26: Student in talks with cuku finance, has asked to reconnect with proplld (initially rejected the same), interested in offering by gyandhan. Prob sol: - Student admitted that he initially rejected proppld , but realised in his case he wont get the product he wants so seems more flexible with the offerings. 17/7 : Student is panicking because of the loan , student told he wouldn't be able to handle the interest monthly. He is a drop student. 18/7 : Student's last year of the admission. Student is worried about the monthly expenses and is a good student. He has been in stress, intent is too high. Student arranged the block from his brother which he has to return. 29/7: Docs pending with GD but a high risk case and not ready to pay high rate of int.. might frop | U40: Yes | V40: Yes | W40: Yes | AA40: Risk | AB40: Risk | AG40: Ongoing | AH40: Processing by GyanDhan | AJ40: Yes | AK40: Yes
...

Sheet 02_Configuration
A1: uGSOT LOAN OPERATIONS — CONFIGURATION
A2: Edit this sheet only to add vendors, stages, mappings. Do not edit formulas on other sheets.
A4: VENDORS
A5: VendorID | B5: VendorName | C5: MasterCol | D5: MasterHeader | E5: Active | F5: SortOrder | G5: StatusToken
A6: 1 | B6: ICICI | C6: V | D6: Shared to ICICI | E6: Yes | F6: 1 | G6: Processing by Icici|Loan sanctioned by Icici
A7: 2 | B7: Propelld | C7: W | D7: Shared to Propelld | E7: Yes | F7: 2 | G7: Processing by Propelld|Loan sanctioned by Propelld|Loan Sanctioned by Proplld
A8: 3 | B8: Study4Buddy | C8: X | D8: Shared to Study4Buddy | E8: Yes | F8: 3 | G8: Processing by Study4Buddy
A9: 4 | B9: Poonawala Fincorp | C9: Y | D9: Shared to Poonawala Fincorp | E9: Yes | F9: 4 | G9: Processing by Poonawala Fincorp
A10: 5 | B10: GyanDhan | C10: Z | D10: Shared to GyanDhan | E10: Yes | F10: 5 | G10: Processing by GyanDhan|Loan sanctioned by gyan dhan
A11: 6 | B11: PM Vidyalakshmi | D11: Special Vidyalaksmi / Loan Status | E11: Yes | F11: 6 | G11: Processing by PM vidyalakshmi
A12: 7 | B12: Other Bank | D12: Loan Status token | E12: Yes | F12: 7 | G12: Processing at other bank|Loan sanctioned by other bank
A13: 8 | B13: State Scheme | D13: Loan Status token | E13: Yes | F13: 8 | G13: State Scheme
A14: 9 | B14: Auxilo | E14: No | F14: 9
A15: 10 | B15: InCred | E15: No | F15: 10
A18: CANONICAL STAGES (Funnel Order)
A19: StageID | B19: StageName | C19: FunnelOrder | D19: FunnelCore | E19: DashboardKPI | F19: Color
A20: 1 | B20: Need Loan | C20: 1 | D20: Yes | E20: Yes | F20: E31C24
A21: 2 | B21: Interested | C21: 2 | D21: No | E21: No | F21: 666666
A22: 3 | B22: Loan Started | C22: 3 | D22: Yes | E22: Yes | F22: 333333
A23: 4 | B23: Documents Pending | C23: 4 | D23: Yes | E23: Yes | F23: B45309
A24: 5 | B24: Vendor Assigned | C24: 5 | D24: No | E24: No | F24: 666666
A25: 6 | B25: Processing | C25: 6 | D25: Yes | E25: Yes | F25: 1D4ED8
A26: 7 | B26: Approved | C26: 7 | D26: Yes | E26: Yes | F26: 1B7A4E
A27: 8 | B27: Sanctioned | C27: 8 | D27: Yes | E27: No | F27: 1B7A4E
A28: 9 | B28: Disbursed | C28: 9 | D28: Yes | E28: Yes | F28: 1B7A4E
A29: 10 | B29: Completed | C29: 10 | D29: No | E29: No | F29: 111111
A30: 11 | B30: Rejected | C30: 90 | D30: No | E30: Yes | F30: E31C24
A31: 12 | B31: Refund | C31: 91 | D31: No | E31: No | F31: 6B6B6B
... A34: 15 | B34: Unclassified | C34: 99 | D34: No | E34: No | F34: 6B6B6B
A38: CAMPUS NORMALIZATION | D38: AGEING BUCKETS
A39: RawValue | B39: Normalized | C39: Active | D39: Bucket | E39: MinDays | F39: MaxDays
A40: SSAHE | B40: SSAHE | C40: Yes | D40: 0–3 Days | E40: 0 | F40: 3
A41: SSHAE | B41: SSAHE | C41: Yes | D41: 4–7 Days | E41: 4 | F41: 7
A42: ssHAE | B42: SSAHE | C42: Yes | D42: 8–15 Days | E42: 8 | F42: 15
A43: ssahe | B43: SSAHE | C43: Yes | D43: 16–30 Days | E43: 16 | F43: 30
A44: ADYPU | B44: ADYPU | C44: Yes | D44: 30+ Days | E44: 31 | F44: 9999
D45: Unknown | E45: -1 | F45: -1
A48: REASON BUCKETS (keyword → bucket) | D48: RISK FLAGS
A49: Keyword | B49: Bucket | D49: FlagName | E49: MasterCol | F49: YesValue
A50: DNP | B50: Unreachable / DNP | D50: Need FLDG | E50: AI | F50: Yes
...

Sheet 03_Helper
A1: RowNum | B1: StudentKey | C1: StudentName | D1: Mobile | E1: ProvisionalID | F1: CampusRaw | G1: Campus | H1: LoanRequired | I1: NeedLoanSST | J1: Criticality | K1: Scholarship | L1: SharedICICI | M1: SharedPropelld | N1: SharedStudy4Buddy | O1: SharedPoonawala | P1: SharedGyanDhan | Q1: VendorCount | R1: DuplicateVendorFlag | S1: VendorsApplied | T1: PrimaryVendor | U1: CaseStatus | V1: LoanStageRaw | W1: LoanStatusRaw | X1: CanonicalStage | Y1: ApprovalStatus | Z1: DisbursementStatus | AA1: RiskCategory | AB1: CriticalFlag | AC1: NeedFLDG | AD1: NeedVidyalakshmi | AE1: NeedVishwa | AF1: ReasonRaw | AG1: ReasonBucket | AH1: TentativeDate | AI1: PendingDays | AJ1: AgeingBucket | AK1: IsLoanPipeline | AL1: PranjalComments | AM1: SSTRemarks | AN1: LoanAmt | AO1: Income | AP1: ProcessingByICICI | AQ1: ProcessingByPropelld | AR1: ProcessingByGyanDhan | AS1: ProcessingByVidya | AT1: ProcessingByOther | AU1: IsSanctioned | AV1: IsDocsPending | AW1: IsRejectedStatus
A2: =IF('01_Master_Data'!B2="","",1) | B2: =IF('01_Master_Data'!B2="","",IF('01_Master_Data'!C2<>"","MOB|"&TEXT('01_Master_Data'!C2,"0"),IF('01_Master_Data'!D2<>"","PID|"&TRIM('01_Master_Data'!D2&""),""))) | C2: =IF('01_Master_Data'!B2="","",'01_Master_Data'!B2) | D2: =IF('01_Master_Data'!B2="","",'01_Master_Data'!C2) | E2: =IF('01_Master_Data'!B2="","",'01_Master_Data'!D2) | F2: =IF('01_Master_Data'!B2="","",'01_Master_Data'!E2) | G2: =IF('01_Master_Data'!B2="","",IFERROR(VLOOKUP(TRIM('01_Master_Data'!E2&""),'02_Configuration'!$A$40:$B$44,2,FALSE),UPPER(TRIM('01_Master_Data'!E2&"")))) | H2: =IF('01_Master_Data'!B2="","",IF('01_Master_Data'!U2="","",TRIM('01_Master_Data'!U2&""))) | I2: =IF('01_Master_Data'!B2="","",TRIM('01_Master_Data'!F2&"")) | J2: =IF('01_Master_Data'!B2="","",TRIM('01_Master_Data'!G2&"")) | K2: =IF('01_Master_Data'!B2="","",'01_Master_Data'!H2) | L2: =IF('01_Master_Data'!B2="","",IF(LOWER(TRIM('01_Master_Data'!V2&""))="yes",1,0)) | M2: =IF('01_Master_Data'!B2="","",IF(LOWER(TRIM('01_Master_Data'!W2&""))="yes",1,0)) | N2: =IF('01_Master_Data'!B2="","",IF(LOWER(TRIM('01_Master_Data'!X2&""))="yes",1,0)) | O2: =IF('01_Master_Data'!B2="","",IF(LOWER(TRIM('01_Master_Data'!Y2&""))="yes",1,0)) | P2: =IF('01_Master_Data'!B2="","",IF(LOWER(TRIM('01_Master_Data'!Z2&""))="yes",1,0)) | Q2: =IF(A2="","",L2+M2+N2+O2+P2) | R2: =IF(A2="","",IF(Q2>1,"Yes","No")) | S2: =IF(A2="","",TEXTJOIN(", ",TRUE,IF(L2=1,"ICICI",""),IF(M2=1,"Propelld",""),IF(N2=1,"Study4Buddy",""),IF(O2=1,"Poonawala Fincorp",""),IF(P2=1,"GyanDhan",""))) | T2: =IF(A2="","",IF(L2=1,"ICICI",IF(M2=1,"Propelld",IF(P2=1,"GyanDhan",IF(N2=1,"Study4Buddy",IF(O2=1,"Poonawala Fincorp",IF(ISNUMBER(SEARCH("GyanDhan",W2&"")),"GyanDhan",IF(ISNUMBER(SEARCH("Icici",W2&"")),"ICICI",IF(ISNUMBER(SEARCH("Propelld",W2&"")),"Propelld",IF(ISNUMBER(SEARCH("vidyalakshmi",LOWER(W2&"")),"PM Vidyalakshmi","—")))))))))) | U2: =IF(A2="","",TRIM('01_Master_Data'!AA2&"")) | V2: =IF(A2="","",TRIM('01_Master_Data'!AG2&"")) | W2: =IF(A2="","",TRIM('01_Master_Data'!AH2&"")) | X2: =IF(A2="","",IF(OR(LOWER(H2)="refund",LOWER(U2)="refund case"),"Refund",IF(OR(LOWER(H2)="dnp",LOWER(U2)="dnp"),"DNP",IF(OR(LOWER(V2)="disbursed",ISNUMBER(SEARCH("Disbursed",W2&""))),"Disbursed",IF(OR(LOWER(V2)="loan proccessed/accepted",ISNUMBER(SEARCH("sanctioned",LOWER(W2&"")))),"Sanctioned",IF(OR(LOWER(V2)="rejected",ISNUMBER(SEARCH("Not eligbile",W2&"")),ISNUMBER(SEARCH("Not eligible",W2&""))),"Rejected",IF(ISNUMBER(SEARCH("Docs Pending",W2&"")),"Documents Pending",IF(AND(LOWER(H2)="yes",LOWER(V2)="ongoing"),"Processing",IF(AND(LOWER(H2)="yes",Q2>0,OR(V2="",LOWER(V2)="not even started")),"Vendor Assigned",IF(AND(LOWER(H2)="yes",LOWER(V2)="not even started"),"Need Loan",IF(LOWER(H2)="yes","Loan Started",IF(LOWER(H2)="not sure","Interested",IF(OR(LOWER(H2)="no",LOWER(V2)="not required"),"Not Required","Unclassified"))))))))))))) | Y2: =IF(A2="","",IF(OR(X2="Sanctioned",X2="Disbursed",X2="Approved"),"Approved",IF(X2="Rejected","Rejected",IF(OR(X2="Processing",X2="Documents Pending",X2="Vendor Assigned"),"In Progress",IF(X2="Need Loan","Pending Start","—")))) | Z2: =IF(A2="","",IF(X2="Disbursed","Disbursed",IF(X2="Sanctioned","Sanctioned - Awaiting Disbursement","Not Disbursed"))) | AA2: =IF(A2="","",IF(LOWER(TRIM('01_Master_Data'!AI2&""))="yes","Need FLDG",IF(LOWER(TRIM('01_Master_Data'!AK2&""))="yes","Need Vidyalakshmi",IF(LOWER(TRIM('01_Master_Data'!AJ2&""))="yes","Need Review",IF(LOWER(J2)="critical","Critical",IF(LOWER(U2)="risk","Risk Case",IF(X2="Refund","Refund","Normal"))))))) | AB2: =IF(A2="","",IF(OR(LOWER(J2)="critical",LOWER(TRIM('01_Master_Data'!AI2&""))="yes",LOWER(TRIM('01_Master_Data'!AK2&""))="yes",LOWER(U2)="risk"),"Yes","No")) | AC2: =IF(A2="","",IF(LOWER(TRIM('01_Master_Data'!AI2&""))="yes","Yes","No")) | AD2: =IF(A2="","",IF(LOWER(TRIM('01_Master_Data'!AK2&""))="yes","Yes","No")) | AE2: =IF(A2="","",IF(LOWER(TRIM('01_Master_Data'!AJ2&""))="yes","Yes","No")) | AF2: =IF(A2="","",TRIM('01_Master_Data'!AL2&"")) | AG2: =IF(A2="","",IF(AF2="","—",IF(ISNUMBER(SEARCH("DNP",AF2)),"Unreachable / DNP",IF(ISNUMBER(SEARCH("interest",LOWER(AF2))),"High Interest / Terms",IF(OR(ISNUMBER(SEARCH("eligib",LOWER(AF2))),ISNUMBER(SEARCH("income",LOWER(AF2)))),"Eligibility / Income",IF(OR(ISNUMBER(SEARCH("start",LOWER(AF2))),ISNUMBER(SEARCH("Newer",AF2)),ISNUMBER(SEARCH("Will start",AF2))),"Process Yet to Start",IF(ISNUMBER(SEARCH("sure",LOWER(AF2))),"Undecided",IF(OR(ISNUMBER(SEARCH("reject",LOWER(AF2))),ISNUMBER(SEARCH("SBI",AF2))),"Rejected Elsewhere",IF(ISNUMBER(SEARCH("call",LOWER(AF2))),"Bank Communication",IF(OR(ISNUMBER(SEARCH("father",LOWER(AF2))),ISNUMBER(SEARCH("sister",LOWER(AF2)))),"Family / Dependency","Other")))))))))) | AH2: =IF(A2="","",'01_Master_Data'!AC2) | AI2: =IF(A2="","",IF(OR(AH2="",NOT(ISNUMBER(AH2))),"",MAX(0,'02_Configuration'!$B$82-AH2))) | AJ2: =IF(A2="","",IF(AI2="","Unknown",IF(AI2<=3,"0–3 Days",IF(AI2<=7,"4–7 Days",IF(AI2<=15,"8–15 Days",IF(AI2<=30,"16–30 Days","30+ Days")))))) | AK2: =IF(A2="","",IF(LOWER(H2)="yes","Yes","No")) | AL2: =IF(A2="","",'01_Master_Data'!T2) | AM2: =IF(A2="","",'01_Master_Data'!S2) | AN2: =IF(A2="","",'01_Master_Data'!I2) | AO2: =IF(A2="","",'01_Master_Data'!M2) | AP2: =IF(A2="","",IF(ISNUMBER(SEARCH("Icici",W2&"")),1,0)) | AQ2: =IF(A2="","",IF(ISNUMBER(SEARCH("Propelld",W2&"")),1,0)) | AR2: =IF(A2="","",IF(ISNUMBER(SEARCH("GyanDhan",W2&"")),1,0)) | AS2: =IF(A2="","",IF(ISNUMBER(SEARCH("vidyalakshmi",LOWER(W2&""))),1,0)) | AT2: =IF(A2="","",IF(ISNUMBER(SEARCH("other bank",LOWER(W2&""))),1,0)) | AU2: =IF(A2="","",IF(ISNUMBER(SEARCH("sanctioned",LOWER(W2&""))),1,0)) | AV2: =IF(A2="","",IF(ISNUMBER(SEARCH("Docs Pending",W2&"")),1,0)) | AW2: =IF(A2="","",IF(OR(X2="Rejected",ISNUMBER(SEARCH("Not eligbile",W2&""))),1,0))
A3: =IF('01_Master_Data'!B3="","",2) | B3: =IF('01_Master_Data'!B3="","",IF('01_Master_Data'!C3<>"","MOB|"&TEXT('01_Master_Data'!C3,"0"),IF('01_Master_Data'!D3<>"","PID|"&TRIM('01_Master_Data'!D3&""),""))) | C3: =IF('01_Master_Data'!B3="","",'01_Master_Data'!B3) | D3: =IF('01_Master_Data'!B3="","",'01_Master_Data'!C3) | E3: =IF('01_Master_Data'!B3="","",'01_Master_Data'!D3) | F3: =IF('01_Master_Data'!B3="","",'01_Master_Data'!E3) | G3: =IF('01_Master_Data'!B3="","",IFERROR(VLOOKUP(TRIM('01_Master_Data'!E3&""),'02_Configuration'!$A$40:$B$44,2,FALSE),UPPER(TRIM('01_Master_Data'!E3&"")))) | H3: =IF('01_Master_Data'!B3="","",IF('01_Master_Data'!U3="","",TRIM('01_Master_Data'!U3&""))) | I3: =IF('01_Master_Data'!B3="","",TRIM('01_Master_Data'!F3&"")) | J3: =IF('01_Master_Data'!B3="","",TRIM('01_Master_Data'!G3&"")) | K3: =IF('01_Master_Data'!B3="","",'01_Master_Data'!H3) | L3: =IF('01_Master_Data'!B3="","",IF(LOWER(TRIM('01_Master_Data'!V3&""))="yes",1,0)) | M3: =IF('01_Master_Data'!B3="","",IF(LOWER(TRIM('01_Master_Data'!W3&""))="yes",1,0)) | N3: =IF('01_Master_Data'!B3="","",IF(LOWER(TRIM('01_Master_Data'!X3&""))="yes",1,0)) | O3: =IF('01_Master_Data'!B3="","",IF(LOWER(TRIM('01_Master_Data'!Y3&""))="yes",1,0)) | P3: =IF('01_Master_Data'!B3="","",IF(LOWER(TRIM('01_Master_Data'!Z3&""))="yes",1,0)) | Q3: =IF(A3="","",L3+M3+N3+O3+P3) | R3: =IF(A3="","",IF(Q3>1,"Yes","No")) | S3: =IF(A3="","",TEXTJOIN(", ",TRUE,IF(L3=1,"ICICI",""),IF(M3=1,"Propelld",""),IF(N3=1,"Study4Buddy",""),IF(O3=1,"Poonawala Fincorp",""),IF(P3=1,"GyanDhan",""))) | T3: =IF(A3="","",IF(L3=1,"ICICI",IF(M3=1,"Propelld",IF(P3=1,"GyanDhan",IF(N3=1,"Study4Buddy",IF(O3=1,"Poonawala Fincorp",IF(ISNUMBER(SEARCH("GyanDhan",W3&"")),"GyanDhan",IF(ISNUMBER(SEARCH("Icici",W3&"")),"ICICI",IF(ISNUMBER(SEARCH("Propelld",W3&"")),"Propelld",IF(ISNUMBER(SEARCH("vidyalakshmi",LOWER(W3&"")),"PM Vidyalakshmi","—")))))))))) | U3: =IF(A3="","",TRIM('01_Master_Data'!AA3&"")) | V3: =IF(A3="","",TRIM('01_Master_Data'!AG3&"")) | W3: =IF(A3="","",TRIM('01_Master_Data'!AH3&"")) | X3: =IF(A3="","",IF(OR(LOWER(H3)="refund",LOWER(U3)="refund case"),"Refund",IF(OR(LOWER(H3)="dnp",LOWER(U3)="dnp"),"DNP",IF(OR(LOWER(V3)="disbursed",ISNUMBER(SEARCH("Disbursed",W3&""))),"Disbursed",IF(OR(LOWER(V3)="loan proccessed/accepted",ISNUMBER(SEARCH("sanctioned",LOWER(W3&"")))),"Sanctioned",IF(OR(LOWER(V3)="rejected",ISNUMBER(SEARCH("Not eligbile",W3&"")),ISNUMBER(SEARCH("Not eligible",W3&""))),"Rejected",IF(ISNUMBER(SEARCH("Docs Pending",W3&"")),"Documents Pending",IF(AND(LOWER(H3)="yes",LOWER(V3)="ongoing"),"Processing",IF(AND(LOWER(H3)="yes",Q3>0,OR(V3="",LOWER(V3)="not even started")),"Vendor Assigned",IF(AND(LOWER(H3)="yes",LOWER(V3)="not even started"),"Need Loan",IF(LOWER(H3)="yes","Loan Started",IF(LOWER(H3)="not sure","Interested",IF(OR(LOWER(H3)="no",LOWER(V3)="not required"),"Not Required","Unclassified"))))))))))))) | Y3: =IF(A3="","",IF(OR(X3="Sanctioned",X3="Disbursed",X3="Approved"),"Approved",IF(X3="Rejected","Rejected",IF(OR(X3="Processing",X3="Documents Pending",X3="Vendor Assigned"),"In Progress",IF(X3="Need Loan","Pending Start","—")))) | Z3: =IF(A3="","",IF(X3="Disbursed","Disbursed",IF(X3="Sanctioned","Sanctioned - Awaiting Disbursement","Not Disbursed"))) | AA3: =IF(A3="","",IF(LOWER(TRIM('01_Master_Data'!AI3&""))="yes","Need FLDG",IF(LOWER(TRIM('01_Master_Data'!AK3&""))="yes","Need Vidyalakshmi",IF(LOWER(TRIM('01_Master_Data'!AJ3&""))="yes","Need Review",IF(LOWER(J3)="critical","Critical",IF(LOWER(U3)="risk","Risk Case",IF(X3="Refund","Refund","Normal"))))))) | AB3: =IF(A3="","",IF(OR(LOWER(J3)="critical",LOWER(TRIM('01_Master_Data'!AI3&""))="yes",LOWER(TRIM('01_Master_Data'!AK3&""))="yes",LOWER(U3)="risk"),"Yes","No")) | AC3: =IF(A3="","",IF(LOWER(TRIM('01_Master_Data'!AI3&""))="yes","Yes","No")) | AD3: =IF(A3="","",IF(LOWER(TRIM('01_Master_Data'!AK3&""))="yes","Yes","No")) | AE3: =IF(A3="","",IF(LOWER(TRIM('01_Master_Data'!AJ3&""))="yes","Yes","No")) | AF3: =IF(A3="","",TRIM('01_Master_Data'!AL3&"")) | AG3: =IF(A3="","",IF(AF3="","—",IF(ISNUMBER(SEARCH("DNP",AF3)),"Unreachable / DNP",IF(ISNUMBER(SEARCH("interest",LOWER(AF3))),"High Interest / Terms",IF(OR(ISNUMBER(SEARCH("eligib",LOWER(AF3))),ISNUMBER(SEARCH("income",LOWER(AF3)))),"Eligibility / Income",IF(OR(ISNUMBER(SEARCH("start",LOWER(AF3))),ISNUMBER(SEARCH("Newer",AF3)),ISNUMBER(SEARCH("Will start",AF3))),"Process Yet to Start",IF(ISNUMBER(SEARCH("sure",LOWER(AF3))),"Undecided",IF(OR(ISNUMBER(SEARCH("reject",LOWER(AF3))),ISNUMBER(SEARCH("SBI",AF3))),"Rejected Elsewhere",IF(ISNUMBER(SEARCH("call",LOWER(AF3))),"Bank Communication",IF(OR(ISNUMBER(SEARCH("father",LOWER(AF3))),ISNUMBER(SEARCH("sister",LOWER(AF3)))),"Family / Dependency","Other")))))))))) | AH3: =IF(A3="","",'01_Master_Data'!AC3) | AI3: =IF(A3="","",IF(OR(AH3="",NOT(ISNUMBER(AH3))),"",MAX(0,'02_Configuration'!$B$82-AH3))) | AJ3: =IF(A3="","",IF(AI3="","Unknown",IF(AI3<=3,"0–3 Days",IF(AI3<=7,"4–7 Days",IF(AI3<=15,"8–15 Days",IF(AI3<=30,"16–30 Days","30+ Days")))))) | AK3: =IF(A3="","",IF(LOWER(H3)="yes","Yes","No")) | AL3: =IF(A3="","",'01_Master_Data'!T3) | AM3: =IF(A3="","",'01_Master_Data'!S3) | AN3: =IF(A3="","",'01_Master_Data'!I3) | AO3: =IF(A3="","",'01_Master_Data'!M3) | AP3: =IF(A3="","",IF(ISNUMBER(SEARCH("Icici",W3&"")),1,0)) | AQ3: =IF(A3="","",IF(ISNUMBER(SEARCH("Propelld",W3&"")),1,0)) | AR3: =IF(A3="","",IF(ISNUMBER(SEARCH("GyanDhan",W3&"")),1,0)) | AS3: =IF(A3="","",IF(ISNUMBER(SEARCH("vidyalakshmi",LOWER(W3&""))),1,0)) | AT3: =IF(A3="","",IF(ISNUMBER(SEARCH("other bank",LOWER(W3&""))),1,0)) | AU3: =IF(A3="","",IF(ISNUMBER(SEARCH("sanctioned",LOWER(W3&""))),1,0)) | AV3: =IF(A3="","",IF(ISNUMBER(SEARCH("Docs Pending",W3&"")),1,0)) | AW3: =IF(A3="","",IF(OR(X3="Rejected",ISNUMBER(SEARCH("Not eligbile",W3&""))),1,0))
